<sdf version='1.7'>
  <world name='CRANE-X7 with Table'>
    <scene>
      <shadows>0</shadows>
      <ambient>0.4 0.4 0.4 1</ambient>
      <background>0.7 0.7 0.7 1</background>
    </scene>
    <light name='sun' type='directional'>
      <cast_shadows>1</cast_shadows>
      <pose>0 0 10 0 -0 0</pose>
      <diffuse>0.8 0.8 0.8 1</diffuse>
      <specular>0.2 0.2 0.2 1</specular>
      <attenuation>
        <range>1000</range>
        <constant>0.9</constant>
        <linear>0.01</linear>
        <quadratic>0.001</quadratic>
      </attenuation>
      <direction>-0.5 0.1 -0.9</direction>
      <spot>
        <inner_angle>0</inner_angle>
        <outer_angle>0</outer_angle>
        <falloff>0</falloff>
      </spot>
    </light>
    <model name='table'>
      <frame name='table::__model__' attached_to='table::link'>
        <pose relative_to='__model__'>0 0 0 0 -0 0</pose>
      </frame>
      <static>1</static>
      <link name='table::link'>
        <collision name='surface'>
          <pose>0 0 1 0 -0 0</pose>
          <geometry>
            <box>
              <size>1.5 0.8 0.03</size>
            </box>
          </geometry>
          <surface>
            <friction>
              <ode>
                <mu>0.6</mu>
                <mu2>0.6</mu2>
              </ode>
              <torsional>
                <ode/>
              </torsional>
            </friction>
            <contact>
              <ode/>
            </contact>
            <bounce/>
          </surface>
          <max_contacts>10</max_contacts>
        </collision>
        <visual name='visual1'>
          <pose>0 0 1 0 -0 0</pose>
          <geometry>
            <box>
              <size>1.5 0.8 0.03</size>
            </box>
          </geometry>
          <material>
            <script>
              <uri>file://media/materials/scripts/gazebo.material</uri>
              <name>Gazebo/Wood</name>
            </script>
          </material>
        </visual>
        <collision name='front_left_leg'>
          <pose>0.68 0.38 0.5 0 -0 0</pose>
          <geometry>
            <cylinder>
              <radius>0.02</radius>
              <length>1</length>
            </cylinder>
          </geometry>
          <max_contacts>10</max_contacts>
          <surface>
            <contact>
              <ode/>
            </contact>
            <bounce/>
            <friction>
              <torsional>
                <ode/>
              </torsional>
              <ode/>
            </friction>
          </surface>
        </collision>
        <visual name='front_left_leg'>
          <pose>0.68 0.38 0.5 0 -0 0</pose>
          <geometry>
            <cylinder>
              <radius>0.02</radius>
              <length>1</length>
            </cylinder>
          </geometry>
          <material>
            <script>
              <uri>file://media/materials/scripts/gazebo.material</uri>
              <name>Gazebo/Grey</name>
            </script>
          </material>
        </visual>
        <collision name='front_right_leg'>
          <pose>0.68 -0.38 0.5 0 -0 0</pose>
          <geometry>
            <cylinder>
              <radius>0.02</radius>
              <length>1</length>
            </cylinder>
          </geometry>
          <max_contacts>10</max_contacts>
          <surface>
            <contact>
              <ode/>
            </contact>
            <bounce/>
            <friction>
              <torsional>
                <ode/>
              </torsional>
              <ode/>
            </friction>
          </surface>
        </collision>
        <visual name='front_right_leg'>
          <pose>0.68 -0.38 0.5 0 -0 0</pose>
          <geometry>
            <cylinder>
              <radius>0.02</radius>
              <length>1</length>
            </cylinder>
          </geometry>
          <material>
            <script>
              <uri>file://media/materials/scripts/gazebo.material</uri>
              <name>Gazebo/Grey</name>
            </script>
          </material>
        </visual>
        <collision name='back_right_leg'>
          <pose>-0.68 -0.38 0.5 0 -0 0</pose>
          <geometry>
            <cylinder>
              <radius>0.02</radius>
              <length>1</length>
            </cylinder>
          </geometry>
          <max_contacts>10</max_contacts>
          <surface>
            <contact>
              <ode/>
            </contact>
            <bounce/>
            <friction>
              <torsional>
                <ode/>
              </torsional>
              <ode/>
            </friction>
          </surface>
        </collision>
        <visual name='back_right_leg'>
          <pose>-0.68 -0.38 0.5 0 -0 0</pose>
          <geometry>
            <cylinder>
              <radius>0.02</radius>
              <length>1</length>
            </cylinder>
          </geometry>
          <material>
            <script>
              <uri>file://media/materials/scripts/gazebo.material</uri>
              <name>Gazebo/Grey</name>
            </script>
          </material>
        </visual>
        <collision name='back_left_leg'>
          <pose>-0.68 0.38 0.5 0 -0 0</pose>
          <geometry>
            <cylinder>
              <radius>0.02</radius>
              <length>1</length>
            </cylinder>
          </geometry>
          <max_contacts>10</max_contacts>
          <surface>
            <contact>
              <ode/>
            </contact>
            <bounce/>
            <friction>
              <torsional>
                <ode/>
              </torsional>
              <ode/>
            </friction>
          </surface>
        </collision>
        <visual name='back_left_leg'>
          <pose>-0.68 0.38 0.5 0 -0 0</pose>
          <geometry>
            <cylinder>
              <radius>0.02</radius>
              <length>1</length>
            </cylinder>
          </geometry>
          <material>
            <script>
              <uri>file://media/materials/scripts/gazebo.material</uri>
              <name>Gazebo/Grey</name>
            </script>
          </material>
        </visual>
        <pose relative_to='table::__model__'>0 0 0 0 -0 0</pose>
        <self_collide>0</self_collide>
        <enable_wind>0</enable_wind>
        <kinematic>0</kinematic>
      </link>
      <pose>0.29 0 0 0 -0 1.5708</pose>
    </model>
    <model name='ground_plane'>
      <frame name='ground_plane::__model__' attached_to='ground_plane::link'>
        <pose relative_to='__model__'>0 0 0 0 -0 0</pose>
      </frame>
      <static>1</static>
      <link name='ground_plane::link'>
        <collision name='collision'>
          <geometry>
            <plane>
              <normal>0 0 1</normal>
              <size>100 100</size>
            </plane>
          </geometry>
          <surface>
            <friction>
              <ode>
                <mu>100</mu>
                <mu2>50</mu2>
              </ode>
              <torsional>
                <ode/>
              </torsional>
            </friction>
            <contact>
              <ode/>
            </contact>
            <bounce/>
          </surface>
          <max_contacts>10</max_contacts>
        </collision>
        <visual name='visual'>
          <cast_shadows>0</cast_shadows>
          <geometry>
            <plane>
              <normal>0 0 1</normal>
              <size>100 100</size>
            </plane>
          </geometry>
          <material>
            <script>
              <uri>file://media/materials/scripts/gazebo.material</uri>
              <name>Gazebo/Grey</name>
            </script>
          </material>
        </visual>
        <pose relative_to='ground_plane::__model__'>0 0 0 0 -0 0</pose>
        <self_collide>0</self_collide>
        <enable_wind>0</enable_wind>
        <kinematic>0</kinematic>
      </link>
      <joint name='ground_joint' type='fixed'>
        <parent>ground_plane::link</parent>
        <child>table::link</child>
      </joint>
    </model>
    <gravity>0 0 -9.8</gravity>
    <magnetic_field>6e-06 2.3e-05 -4.2e-05</magnetic_field>
    <atmosphere type='adiabatic'/>
    <physics type='ode'>
      <max_step_size>0.001</max_step_size>
      <real_time_factor>1</real_time_factor>
      <real_time_update_rate>1000</real_time_update_rate>
    </physics>
    <wind/>
    <spherical_coordinates>
      <surface_model>EARTH_WGS84</surface_model>
      <latitude_deg>0</latitude_deg>
      <longitude_deg>0</longitude_deg>
      <elevation>0</elevation>
      <heading_deg>0</heading_deg>
    </spherical_coordinates>
    <model name='crane_x7'>
      <joint name='base_link_to_world_joint' type='fixed'>
        <pose relative_to='__model__'>0 0 0 0 -0 0</pose>
        <parent>world</parent>
        <child>base_link</child>
      </joint>
      <link name='base_link'>
        <pose relative_to='base_link_to_world_joint'>0 0 0 0 -0 0</pose>
        <inertial>
          <pose>-0.00673 -1e-06 0.0229 0 -0 0</pose>
          <mass>0.388</mass>
          <inertia>
            <ixx>0.000325</ixx>
            <ixy>1.2e-09</ixy>
            <ixz>-4.71e-05</ixz>
            <iyy>0.000483</iyy>
            <iyz>1.95e-08</iyz>
            <izz>0.000586</izz>
          </inertia>
        </inertial>
        <collision name='base_link_fixed_joint_lump__crane_x7_mounting_plate_link_collision'>
          <pose>0 0 0 0 -0 0</pose>
          <geometry>
            <mesh>
              <scale>1 1 1</scale>
              <uri>/home/shiokaze/catkin_ws/src/crane_x7_description/meshes/collision/mounting_plate.stl</uri>
            </mesh>
          </geometry>
          <surface>
            <contact>
              <ode/>
            </contact>
            <friction>
              <ode/>
              <torsional>
                <ode/>
              </torsional>
            </friction>
            <bounce/>
          </surface>
          <max_contacts>10</max_contacts>
        </collision>
        <collision name='base_link_fixed_joint_lump__crane_x7_shoulder_fixed_part_link_collision_1'>
          <pose>0 0 0.005 0 -0 0</pose>
          <geometry>
            <mesh>
              <scale>1 1 1</scale>
              <uri>/home/shiokaze/catkin_ws/src/crane_x7_description/meshes/collision/base_fixed_part.stl</uri>
            </mesh>
          </geometry>
          <surface>
            <contact>
              <ode/>
            </contact>
            <friction>
              <ode/>
              <torsional>
                <ode/>
              </torsional>
            </friction>
            <bounce/>
          </surface>
          <max_contacts>10</max_contacts>
        </collision>
        <visual name='base_link_fixed_joint_lump__crane_x7_mounting_plate_link_visual'>
          <pose>0 0 0 0 -0 0</pose>
          <geometry>
            <mesh>
              <scale>1 1 1</scale>
              <uri>/home/shiokaze/catkin_ws/src/crane_x7_description/meshes/visual/mounting_plate.stl</uri>
            </mesh>
          </geometry>
          <material>
            <script>
              <name>Gazebo/Black</name>
              <uri>file://media/materials/scripts/gazebo.material</uri>
            </script>
          </material>
        </visual>
        <visual name='base_link_fixed_joint_lump__crane_x7_shoulder_fixed_part_link_visual_1'>
          <pose>0 0 0.005 0 -0 0</pose>
          <geometry>
            <mesh>
              <scale>1 1 1</scale>
              <uri>/home/shiokaze/catkin_ws/src/crane_x7_description/meshes/visual/base_fixed_part.stl</uri>
            </mesh>
          </geometry>
          <material>
            <script>
              <name>Gazebo/Red</name>
              <uri>file://media/materials/scripts/gazebo.material</uri>
            </script>
          </material>
        </visual>
        <self_collide>0</self_collide>
        <enable_wind>0</enable_wind>
        <kinematic>0</kinematic>
      </link>
      <joint name='crane_x7_shoulder_fixed_part_pan_joint' type='revolute'>
        <pose relative_to='base_link'>0 0 0.041 0 -0 0</pose>
        <parent>base_link</parent>
        <child>crane_x7_shoulder_revolute_part_link</child>
        <axis>
          <xyz>0 0 1</xyz>
          <limit>
            <lower>-2.97132</lower>
            <upper>2.97132</upper>
            <effort>10</effort>
            <velocity>4.81711</velocity>
          </limit>
          <dynamics>
            <damping>1e-06</damping>
            <friction>0.2</friction>
            <spring_reference>0</spring_reference>
            <spring_stiffness>0</spring_stiffness>
          </dynamics>
        </axis>
      </joint>
      <link name='crane_x7_shoulder_revolute_part_link'>
        <pose relative_to='crane_x7_shoulder_fixed_part_pan_joint'>0 0 0 0 -0 0</pose>
        <inertial>
          <pose>0.000243 -0.000105 0.047 0 -0 0</pose>
          <mass>0.253</mass>
          <inertia>
            <ixx>0.000179</ixx>
            <ixy>-7.32e-08</ixy>
            <ixz>8.89e-07</ixz>
            <iyy>0.000176</iyy>
            <iyz>6.23e-07</iyz>
            <izz>8.96e-05</izz>
          </inertia>
        </inertial>
        <collision name='crane_x7_shoulder_revolute_part_link_collision'>
          <pose>0 0 0.0296 0 -0 0</pose>
          <geometry>
            <cylinder>
              <length>0.0295</length>
              <radius>0.0334</radius>
            </cylinder>
          </geometry>
          <surface>
            <contact>
              <ode/>
            </contact>
            <friction>
              <ode/>
              <torsional>
                <ode/>
              </torsional>
            </friction>
            <bounce/>
          </surface>
          <max_contacts>10</max_contacts>
        </collision>
        <collision name='crane_x7_shoulder_revolute_part_link_collision_1'>
          <pose>0 0 0.064 1.57079 -0 0</pose>
          <geometry>
            <cylinder>
              <length>0.0491</length>
              <radius>0.034</radius>
            </cylinder>
          </geometry>
          <surface>
            <contact>
              <ode/>
            </contact>
            <friction>
              <ode/>
              <torsional>
                <ode/>
              </torsional>
            </friction>
            <bounce/>
          </surface>
          <max_contacts>10</max_contacts>
        </collision>
        <visual name='crane_x7_shoulder_revolute_part_link_visual'>
          <pose>0 0 0 0 -0 3.14159</pose>
          <geometry>
            <mesh>
              <scale>1 1 1</scale>
              <uri>/home/shiokaze/catkin_ws/src/crane_x7_description/meshes/visual/base_revolute_part.stl</uri>
            </mesh>
          </geometry>
          <material>
            <script>
              <name>Gazebo/White</name>
              <uri>file://media/materials/scripts/gazebo.material</uri>
            </script>
          </material>
        </visual>
        <self_collide>0</self_collide>
        <enable_wind>0</enable_wind>
        <kinematic>0</kinematic>
      </link>
      <joint name='crane_x7_shoulder_revolute_part_tilt_joint' type='revolute'>
        <pose relative_to='crane_x7_shoulder_revolute_part_link'>0 0 0.064 0 -0 0</pose>
        <parent>crane_x7_shoulder_revolute_part_link</parent>
        <child>crane_x7_upper_arm_fixed_part_link</child>
        <axis>
          <xyz>0 -1 0</xyz>
          <limit>
            <lower>-1.57079</lower>
            <upper>1.57079</upper>
            <effort>10</effort>
            <velocity>4.81711</velocity>
          </limit>
          <dynamics>
            <damping>1e-06</damping>
            <friction>0.2</friction>
            <spring_reference>0</spring_reference>
            <spring_stiffness>0</spring_stiffness>
          </dynamics>
        </axis>
      </joint>
      <link name='crane_x7_upper_arm_fixed_part_link'>
        <pose relative_to='crane_x7_shoulder_revolute_part_tilt_joint'>0 0 0 0 -0 0</pose>
        <inertial>
          <pose>3.1e-05 1.9e-05 0.0342 1.57079 -0 0</pose>
          <mass>0.136</mass>
          <inertia>
            <ixx>0.000168</ixx>
            <ixy>2.05e-08</ixy>
            <ixz>-4e-07</ixz>
            <iyy>9.62e-05</iyy>
            <iyz>6.24e-08</iyz>
            <izz>0.000134</izz>
          </inertia>
        </inertial>
        <collision name='crane_x7_upper_arm_fixed_part_link_collision'>
          <pose>0 0 0 1.57079 -0 0</pose>
          <geometry>
            <mesh>
              <scale>1 1 1</scale>
              <uri>/home/shiokaze/catkin_ws/src/crane_x7_description/meshes/collision/rotating_link_type_1_fixed_part.stl</uri>
            </mesh>
          </geometry>
          <surface>
            <contact>
              <ode/>
            </contact>
            <friction>
              <ode/>
              <torsional>
                <ode/>
              </torsional>
            </friction>
            <bounce/>
          </surface>
          <max_contacts>10</max_contacts>
        </collision>
        <collision name='crane_x7_upper_arm_fixed_part_link_fixed_joint_lump__crane_x7_upper_arm_fixed_part_joint_cover_l_link_collision_1'>
          <pose>0 0.0316 0 -1.57079 0 0</pose>
          <geometry>
            <mesh>
              <scale>1 1 1</scale>
              <uri>/home/shiokaze/catkin_ws/src/crane_x7_description/meshes/visual/joint_cover.stl</uri>
            </mesh>
          </geometry>
          <surface>
            <contact>
              <ode/>
            </contact>
            <friction>
              <ode/>
              <torsional>
                <ode/>
              </torsional>
            </friction>
            <bounce/>
          </surface>
          <max_contacts>10</max_contacts>
        </collision>
        <collision name='crane_x7_upper_arm_fixed_part_link_fixed_joint_lump__crane_x7_upper_arm_fixed_part_joint_cover_r_link_collision_2'>
          <pose>0 -0.0316 0 1.57079 -0 0</pose>
          <geometry>
            <mesh>
              <scale>1 1 1</scale>
              <uri>/home/shiokaze/catkin_ws/src/crane_x7_description/meshes/visual/joint_cover.stl</uri>
            </mesh>
          </geometry>
          <surface>
            <contact>
              <ode/>
            </contact>
            <friction>
              <ode/>
              <torsional>
                <ode/>
              </torsional>
            </friction>
            <bounce/>
          </surface>
          <max_contacts>10</max_contacts>
        </collision>
        <visual name='crane_x7_upper_arm_fixed_part_link_visual'>
          <pose>0 0 0 1.57079 -0 0</pose>
          <geometry>
            <mesh>
              <scale>1 1 1</scale>
              <uri>/home/shiokaze/catkin_ws/src/crane_x7_description/meshes/visual/rotating_link_type_1_fixed_part.stl</uri>
            </mesh>
          </geometry>
          <material>
            <script>
              <name>Gazebo/White</name>
              <uri>file://media/materials/scripts/gazebo.material</uri>
            </script>
          </material>
        </visual>
        <visual name='crane_x7_upper_arm_fixed_part_link_fixed_joint_lump__crane_x7_upper_arm_fixed_part_joint_cover_l_link_visual_1'>
          <pose>0 0.0316 0 -1.57079 0 0</pose>
          <geometry>
            <mesh>
              <scale>1 1 1</scale>
              <uri>/home/shiokaze/catkin_ws/src/crane_x7_description/meshes/visual/joint_cover.stl</uri>
            </mesh>
          </geometry>
          <material>
            <script>
              <name>Gazebo/Red</name>
              <uri>file://media/materials/scripts/gazebo.material</uri>
            </script>
          </material>
        </visual>
        <visual name='crane_x7_upper_arm_fixed_part_link_fixed_joint_lump__crane_x7_upper_arm_fixed_part_joint_cover_r_link_visual_2'>
          <pose>0 -0.0316 0 1.57079 -0 0</pose>
          <geometry>
            <mesh>
              <scale>1 1 1</scale>
              <uri>/home/shiokaze/catkin_ws/src/crane_x7_description/meshes/visual/joint_cover.stl</uri>
            </mesh>
          </geometry>
          <material>
            <script>
              <name>Gazebo/Red</name>
              <uri>file://media/materials/scripts/gazebo.material</uri>
            </script>
          </material>
        </visual>
        <self_collide>0</self_collide>
        <enable_wind>0</enable_wind>
        <kinematic>0</kinematic>
      </link>
      <joint name='crane_x7_upper_arm_revolute_part_twist_joint' type='revolute'>
        <pose relative_to='crane_x7_upper_arm_fixed_part_link'>0 0 0.065 0 -0 0</pose>
        <parent>crane_x7_upper_arm_fixed_part_link</parent>
        <child>crane_x7_upper_arm_revolute_part_link</child>
        <axis>
          <xyz>0 0 1</xyz>
          <limit>
            <lower>-1.57079</lower>
            <upper>1.57079</upper>
            <effort>4</effort>
            <velocity>4.81711</velocity>
          </limit>
          <dynamics>
            <damping>1e-06</damping>
            <friction>0.2</friction>
            <spring_reference>0</spring_reference>
            <spring_stiffness>0</spring_stiffness>
          </dynamics>
        </axis>
      </joint>
      <link name='crane_x7_upper_arm_revolute_part_link'>
        <pose relative_to='crane_x7_upper_arm_revolute_part_twist_joint'>0 0 0 0 -0 0</pose>
        <inertial>
          <pose>-0.0137 -8.1e-05 0.0952 0 -0 0</pose>
          <mass>0.321</mass>
          <inertia>
            <ixx>0.00182</ixx>
            <ixy>7.54e-07</ixy>
            <ixz>-3.73e-05</ixz>
            <iyy>0.00188</iyy>
            <iyz>4.15e-06</iyz>
            <izz>0.000159</izz>
          </inertia>
        </inertial>
        <collision name='crane_x7_upper_arm_revolute_part_link_collision'>
          <pose>0 0 0 0 -0 0</pose>
          <geometry>
            <mesh>
              <scale>1 1 1</scale>
              <uri>/home/shiokaze/catkin_ws/src/crane_x7_description/meshes/collision/rotating_link_type_1_revolute_part.stl</uri>
            </mesh>
          </geometry>
          <surface>
            <contact>
              <ode/>
            </contact>
            <friction>
              <ode/>
              <torsional>
                <ode/>
              </torsional>
            </friction>
            <bounce/>
          </surface>
          <max_contacts>10</max_contacts>
        </collision>
        <visual name='crane_x7_upper_arm_revolute_part_link_visual'>
          <pose>0 0 0 0 -0 0</pose>
          <geometry>
            <mesh>
              <scale>1 1 1</scale>
              <uri>/home/shiokaze/catkin_ws/src/crane_x7_description/meshes/visual/rotating_link_type_1_revolute_part.stl</uri>
            </mesh>
          </geometry>
          <material>
            <script>
              <name>Gazebo/White</name>
              <uri>file://media/materials/scripts/gazebo.material</uri>
            </script>
          </material>
        </visual>
        <self_collide>0</self_collide>
        <enable_wind>0</enable_wind>
        <kinematic>0</kinematic>
      </link>
      <joint name='crane_x7_upper_arm_revolute_part_rotate_joint' type='revolute'>
        <pose relative_to='crane_x7_upper_arm_revolute_part_link'>0 0 0.185 0 -0 0</pose>
        <parent>crane_x7_upper_arm_revolute_part_link</parent>
        <child>crane_x7_lower_arm_fixed_part_link</child>
        <axis>
          <xyz>0 -1 0</xyz>
          <limit>
            <lower>-2.80718</lower>
            <upper>0.04141</upper>
            <effort>4</effort>
            <velocity>4.81711</velocity>
          </limit>
          <dynamics>
            <damping>1e-06</damping>
            <friction>0.2</friction>
            <spring_reference>0</spring_reference>
            <spring_stiffness>0</spring_stiffness>
          </dynamics>
        </axis>
      </joint>
      <link name='crane_x7_lower_arm_fixed_part_link'>
        <pose relative_to='crane_x7_upper_arm_revolute_part_rotate_joint'>0 0 0 0 -0 0</pose>
        <inertial>
          <pose>-0.00939 6.4e-05 0.0804 1.57079 -0 0</pose>
          <mass>0.222</mass>
          <inertia>
            <ixx>0.000489</ixx>
            <ixy>-3.9e-06</ixy>
            <ixz>8.29e-08</ixz>
            <iyy>0.000114</iyy>
            <iyz>2.82e-06</iyz>
            <izz>0.000503</izz>
          </inertia>
        </inertial>
        <collision name='crane_x7_lower_arm_fixed_part_link_collision'>
          <pose>0 0 0 1.57079 -0 0</pose>
          <geometry>
            <mesh>
              <scale>1 1 1</scale>
              <uri>/home/shiokaze/catkin_ws/src/crane_x7_description/meshes/collision/rotating_link_type_2_fixed_part.stl</uri>
            </mesh>
          </geometry>
          <surface>
            <contact>
              <ode/>
            </contact>
            <friction>
              <ode/>
              <torsional>
                <ode/>
              </torsional>
            </friction>
            <bounce/>
          </surface>
          <max_contacts>10</max_contacts>
        </collision>
        <collision name='crane_x7_lower_arm_fixed_part_link_fixed_joint_lump__crane_x7_lower_arm_fixed_part_joint_cover_l_link_collision_1'>
          <pose>0 0.025 0 -1.57079 0 0</pose>
          <geometry>
            <mesh>
              <scale>1 1 1</scale>
              <uri>/home/shiokaze/catkin_ws/src/crane_x7_description/meshes/visual/joint_cover.stl</uri>
            </mesh>
          </geometry>
          <surface>
            <contact>
              <ode/>
            </contact>
            <friction>
              <ode/>
              <torsional>
                <ode/>
              </torsional>
            </friction>
            <bounce/>
          </surface>
          <max_contacts>10</max_contacts>
        </collision>
        <collision name='crane_x7_lower_arm_fixed_part_link_fixed_joint_lump__crane_x7_lower_arm_fixed_part_joint_cover_r_link_collision_2'>
          <pose>0 -0.025 0 1.57079 -0 0</pose>
          <geometry>
            <mesh>
              <scale>1 1 1</scale>
              <uri>/home/shiokaze/catkin_ws/src/crane_x7_description/meshes/visual/joint_cover.stl</uri>
            </mesh>
          </geometry>
          <surface>
            <contact>
              <ode/>
            </contact>
            <friction>
              <ode/>
              <torsional>
                <ode/>
              </torsional>
            </friction>
            <bounce/>
          </surface>
          <max_contacts>10</max_contacts>
        </collision>
        <visual name='crane_x7_lower_arm_fixed_part_link_visual'>
          <pose>0 0 0 1.57079 -0 0</pose>
          <geometry>
            <mesh>
              <scale>1 1 1</scale>
              <uri>/home/shiokaze/catkin_ws/src/crane_x7_description/meshes/visual/rotating_link_type_2_fixed_part.stl</uri>
            </mesh>
          </geometry>
          <material>
            <script>
              <name>Gazebo/White</name>
              <uri>file://media/materials/scripts/gazebo.material</uri>
            </script>
          </material>
        </visual>
        <visual name='crane_x7_lower_arm_fixed_part_link_fixed_joint_lump__crane_x7_lower_arm_fixed_part_joint_cover_l_link_visual_1'>
          <pose>0 0.025 0 -1.57079 0 0</pose>
          <geometry>
            <mesh>
              <scale>1 1 1</scale>
              <uri>/home/shiokaze/catkin_ws/src/crane_x7_description/meshes/visual/joint_cover.stl</uri>
            </mesh>
          </geometry>
          <material>
            <script>
              <name>Gazebo/Red</name>
              <uri>file://media/materials/scripts/gazebo.material</uri>
            </script>
          </material>
        </visual>
        <visual name='crane_x7_lower_arm_fixed_part_link_fixed_joint_lump__crane_x7_lower_arm_fixed_part_joint_cover_r_link_visual_2'>
          <pose>0 -0.025 0 1.57079 -0 0</pose>
          <geometry>
            <mesh>
              <scale>1 1 1</scale>
              <uri>/home/shiokaze/catkin_ws/src/crane_x7_description/meshes/visual/joint_cover.stl</uri>
            </mesh>
          </geometry>
          <material>
            <script>
              <name>Gazebo/Red</name>
              <uri>file://media/materials/scripts/gazebo.material</uri>
            </script>
          </material>
        </visual>
        <self_collide>0</self_collide>
        <enable_wind>0</enable_wind>
        <kinematic>0</kinematic>
      </link>
      <joint name='crane_x7_lower_arm_fixed_part_joint' type='revolute'>
        <pose relative_to='crane_x7_lower_arm_fixed_part_link'>0 0 0.121 0 -0 0</pose>
        <parent>crane_x7_lower_arm_fixed_part_link</parent>
        <child>crane_x7_lower_arm_revolute_part_link</child>
        <axis>
          <xyz>0 0 1</xyz>
          <limit>
            <lower>-2.77343</lower>
            <upper>2.77343</upper>
            <effort>4</effort>
            <velocity>4.81711</velocity>
          </limit>
          <dynamics>
            <damping>1e-06</damping>
            <friction>0.2</friction>
            <spring_reference>0</spring_reference>
            <spring_stiffness>0</spring_stiffness>
          </dynamics>
        </axis>
      </joint>
      <link name='crane_x7_lower_arm_revolute_part_link'>
        <pose relative_to='crane_x7_lower_arm_fixed_part_joint'>0 0 0 0 -0 0</pose>
        <inertial>
          <pose>-8.4e-05 0.000462 0.0637 0 -0 0</pose>
          <mass>0.207</mass>
          <inertia>
            <ixx>0.00029</ixx>
            <ixy>1e-07</ixy>
            <ixz>-4.77e-07</ixz>
            <iyy>0.000257</iyy>
            <iyz>-1.69e-05</iyz>
            <izz>8.75e-05</izz>
          </inertia>
        </inertial>
        <collision name='crane_x7_lower_arm_revolute_part_link_collision'>
          <pose>0 0 0 0 -0 0</pose>
          <geometry>
            <mesh>
              <scale>1 1 1</scale>
              <uri>/home/shiokaze/catkin_ws/src/crane_x7_description/meshes/collision/rotating_link_type_2_revolute_part.stl</uri>
            </mesh>
          </geometry>
          <surface>
            <contact>
              <ode/>
            </contact>
            <friction>
              <ode/>
              <torsional>
                <ode/>
              </torsional>
            </friction>
            <bounce/>
          </surface>
          <max_contacts>10</max_contacts>
        </collision>
        <collision name='crane_x7_lower_arm_revolute_part_link_fixed_joint_lump__crane_x7_lower_arm_revolute_part_logo_symbol_l_link_collision_1'>
          <pose>0 0.0345 0.132 1.57079 1.57079 3.14159</pose>
          <geometry>
            <mesh>
              <scale>1 1 1</scale>
              <uri>/home/shiokaze/catkin_ws/src/crane_x7_description/meshes/visual/rtcorp_logo_rabbit.stl</uri>
            </mesh>
          </geometry>
          <surface>
            <contact>
              <ode/>
            </contact>
            <friction>
              <ode/>
              <torsional>
                <ode/>
              </torsional>
            </friction>
            <bounce/>
          </surface>
          <max_contacts>10</max_contacts>
        </collision>
        <collision name='crane_x7_lower_arm_revolute_part_link_fixed_joint_lump__crane_x7_lower_arm_revolute_part_logo_symbol_r_link_collision_2'>
          <pose>0 -0.0345 0.065 -1.57079 -1.57079 3.14159</pose>
          <geometry>
            <mesh>
              <scale>1 1 1</scale>
              <uri>/home/shiokaze/catkin_ws/src/crane_x7_description/meshes/visual/rtcorp_logo_rabbit.stl</uri>
            </mesh>
          </geometry>
          <surface>
            <contact>
              <ode/>
            </contact>
            <friction>
              <ode/>
              <torsional>
                <ode/>
              </torsional>
            </friction>
            <bounce/>
          </surface>
          <max_contacts>10</max_contacts>
        </collision>
        <collision name='crane_x7_lower_arm_revolute_part_link_fixed_joint_lump__crane_x7_lower_arm_revolute_part_logo_text_l_link_collision_3'>
          <pose>0 0.0345 0.095 1.57079 1.57079 3.14159</pose>
          <geometry>
            <mesh>
              <scale>1 1 1</scale>
              <uri>/home/shiokaze/catkin_ws/src/crane_x7_description/meshes/visual/rtcorp_logo_name.stl</uri>
            </mesh>
          </geometry>
          <surface>
            <contact>
              <ode/>
            </contact>
            <friction>
              <ode/>
              <torsional>
                <ode/>
              </torsional>
            </friction>
            <bounce/>
          </surface>
          <max_contacts>10</max_contacts>
        </collision>
        <collision name='crane_x7_lower_arm_revolute_part_link_fixed_joint_lump__crane_x7_lower_arm_revolute_part_logo_text_r_link_collision_4'>
          <pose>0 -0.0345 0.104 -1.57079 -1.57079 3.14159</pose>
          <geometry>
            <mesh>
              <scale>1 1 1</scale>
              <uri>/home/shiokaze/catkin_ws/src/crane_x7_description/meshes/visual/rtcorp_logo_name.stl</uri>
            </mesh>
          </geometry>
          <surface>
            <contact>
              <ode/>
            </contact>
            <friction>
              <ode/>
              <torsional>
                <ode/>
              </torsional>
            </friction>
            <bounce/>
          </surface>
          <max_contacts>10</max_contacts>
        </collision>
        <visual name='crane_x7_lower_arm_revolute_part_link_visual'>
          <pose>0 0 0 0 -0 0</pose>
          <geometry>
            <mesh>
              <scale>1 1 1</scale>
              <uri>/home/shiokaze/catkin_ws/src/crane_x7_description/meshes/visual/rotating_link_type_2_revolute_part.stl</uri>
            </mesh>
          </geometry>
          <material>
            <script>
              <name>Gazebo/White</name>
              <uri>file://media/materials/scripts/gazebo.material</uri>
            </script>
          </material>
        </visual>
        <visual name='crane_x7_lower_arm_revolute_part_link_fixed_joint_lump__crane_x7_lower_arm_revolute_part_logo_symbol_l_link_visual_1'>
          <pose>0 0.0345 0.132 1.57079 1.57079 3.14159</pose>
          <geometry>
            <mesh>
              <scale>1 1 1</scale>
              <uri>/home/shiokaze/catkin_ws/src/crane_x7_description/meshes/visual/rtcorp_logo_rabbit.stl</uri>
            </mesh>
          </geometry>
          <material>
            <script>
              <name>Gazebo/Red</name>
              <uri>file://media/materials/scripts/gazebo.material</uri>
            </script>
          </material>
        </visual>
        <visual name='crane_x7_lower_arm_revolute_part_link_fixed_joint_lump__crane_x7_lower_arm_revolute_part_logo_symbol_r_link_visual_2'>
          <pose>0 -0.0345 0.065 -1.57079 -1.57079 3.14159</pose>
          <geometry>
            <mesh>
              <scale>1 1 1</scale>
              <uri>/home/shiokaze/catkin_ws/src/crane_x7_description/meshes/visual/rtcorp_logo_rabbit.stl</uri>
            </mesh>
          </geometry>
          <material>
            <script>
              <name>Gazebo/Red</name>
              <uri>file://media/materials/scripts/gazebo.material</uri>
            </script>
          </material>
        </visual>
        <visual name='crane_x7_lower_arm_revolute_part_link_fixed_joint_lump__crane_x7_lower_arm_revolute_part_logo_text_l_link_visual_3'>
          <pose>0 0.0345 0.095 1.57079 1.57079 3.14159</pose>
          <geometry>
            <mesh>
              <scale>1 1 1</scale>
              <uri>/home/shiokaze/catkin_ws/src/crane_x7_description/meshes/visual/rtcorp_logo_name.stl</uri>
            </mesh>
          </geometry>
          <material>
            <script>
              <name>Gazebo/Black</name>
              <uri>file://media/materials/scripts/gazebo.material</uri>
            </script>
          </material>
        </visual>
        <visual name='crane_x7_lower_arm_revolute_part_link_fixed_joint_lump__crane_x7_lower_arm_revolute_part_logo_text_r_link_visual_4'>
          <pose>0 -0.0345 0.104 -1.57079 -1.57079 3.14159</pose>
          <geometry>
            <mesh>
              <scale>1 1 1</scale>
              <uri>/home/shiokaze/catkin_ws/src/crane_x7_description/meshes/visual/rtcorp_logo_name.stl</uri>
            </mesh>
          </geometry>
          <material>
            <script>
              <name>Gazebo/Black</name>
              <uri>file://media/materials/scripts/gazebo.material</uri>
            </script>
          </material>
        </visual>
        <self_collide>0</self_collide>
        <enable_wind>0</enable_wind>
        <kinematic>0</kinematic>
      </link>
      <joint name='crane_x7_lower_arm_revolute_part_joint' type='revolute'>
        <pose relative_to='crane_x7_lower_arm_revolute_part_link'>0 0 0.129 0 -0 0</pose>
        <parent>crane_x7_lower_arm_revolute_part_link</parent>
        <child>crane_x7_wrist_link</child>
        <axis>
          <xyz>0 -1 0</xyz>
          <limit>
            <lower>-1.57079</lower>
            <upper>1.57079</upper>
            <effort>4</effort>
            <velocity>4.81711</velocity>
          </limit>
          <dynamics>
            <damping>1e-06</damping>
            <friction>0.2</friction>
            <spring_reference>0</spring_reference>
            <spring_stiffness>0</spring_stiffness>
          </dynamics>
        </axis>
      </joint>
      <link name='crane_x7_wrist_link'>
        <pose relative_to='crane_x7_lower_arm_revolute_part_joint'>0 0 0 0 -0 0</pose>
        <inertial>
          <pose>0.0061 0.000826 -0.00355 1.57079 -0 0</pose>
          <mass>0.14</mass>
          <inertia>
            <ixx>4.01e-05</ixx>
            <ixy>-2.91e-06</ixy>
            <ixz>6.39e-07</ixz>
            <iyy>6.13e-05</iyy>
            <iyz>-4.9e-07</iyz>
            <izz>7.35e-05</izz>
          </inertia>
        </inertial>
        <collision name='crane_x7_wrist_link_collision'>
          <pose>0 0 0 1.57079 -0 0</pose>
          <geometry>
            <mesh>
              <scale>1 1 1</scale>
              <uri>/home/shiokaze/catkin_ws/src/crane_x7_description/meshes/collision/wrist.stl</uri>
            </mesh>
          </geometry>
          <surface>
            <contact>
              <ode/>
            </contact>
            <friction>
              <ode/>
              <torsional>
                <ode/>
              </torsional>
            </friction>
            <bounce/>
          </surface>
          <max_contacts>10</max_contacts>
        </collision>
        <visual name='crane_x7_wrist_link_visual'>
          <pose>0 0 0 1.57079 -0 0</pose>
          <geometry>
            <mesh>
              <scale>1 1 1</scale>
              <uri>/home/shiokaze/catkin_ws/src/crane_x7_description/meshes/visual/wrist.stl</uri>
            </mesh>
          </geometry>
          <material>
            <script>
              <name>Gazebo/White</name>
              <uri>file://media/materials/scripts/gazebo.material</uri>
            </script>
          </material>
        </visual>
        <self_collide>0</self_collide>
        <enable_wind>0</enable_wind>
        <kinematic>0</kinematic>
      </link>
      <joint name='crane_x7_wrist_joint' type='revolute'>
        <pose relative_to='crane_x7_wrist_link'>0 0 0.019 0 -0 0</pose>
        <parent>crane_x7_wrist_link</parent>
        <child>crane_x7_gripper_base_link</child>
        <axis>
          <xyz>0 0 1</xyz>
          <limit>
            <lower>-2.96365</lower>
            <upper>2.97132</upper>
            <effort>4</effort>
            <velocity>4.81711</velocity>
          </limit>
          <dynamics>
            <damping>1e-06</damping>
            <friction>0.2</friction>
            <spring_reference>0</spring_reference>
            <spring_stiffness>0</spring_stiffness>
          </dynamics>
        </axis>
      </joint>
      <link name='crane_x7_gripper_base_link'>
        <pose relative_to='crane_x7_wrist_joint'>0 0 0 0 -0 0</pose>
        <inertial>
          <pose>1.8e-05 0.036859 0.01098 0 -0 0</pose>
          <mass>0.721</mass>
          <inertia>
            <ixx>0.00125476</ixx>
            <ixy>4.00634e-07</ixy>
            <ixz>1.32676e-07</ixz>
            <iyy>0.00105542</iyy>
            <iyz>5.4486e-05</iyz>
            <izz>0.00125164</izz>
          </inertia>
        </inertial>
        <collision name='crane_x7_gripper_base_link_collision'>
          <pose>0 0 0 0 -0 0</pose>
          <geometry>
            <mesh>
              <scale>1 1 1</scale>
              <uri>/home/shiokaze/catkin_ws/src/crane_x7_description/meshes/collision/wide_two_finger_gripper_actuator.stl</uri>
            </mesh>
          </geometry>
          <surface>
            <contact>
              <ode/>
            </contact>
            <friction>
              <ode/>
              <torsional>
                <ode/>
              </torsional>
            </friction>
            <bounce/>
          </surface>
          <max_contacts>10</max_contacts>
        </collision>
        <collision name='crane_x7_gripper_base_link_fixed_joint_lump__camera_base_collision_1'>
          <pose>0 0.0445 0.021525 1.57079 -1.57079 3.14159</pose>
          <geometry>
            <box>
              <size>0.02505 0.09 0.025</size>
            </box>
          </geometry>
          <max_contacts>10</max_contacts>
          <surface>
            <contact>
              <ode/>
            </contact>
            <bounce/>
            <friction>
              <torsional>
                <ode/>
              </torsional>
              <ode/>
            </friction>
          </surface>
        </collision>
        <visual name='crane_x7_gripper_base_link_visual'>
          <pose>0 0 0 0 -0 0</pose>
          <geometry>
            <mesh>
              <scale>1 1 1</scale>
              <uri>/home/shiokaze/catkin_ws/src/crane_x7_description/meshes/visual/wide_two_finger_gripper_actuator.stl</uri>
            </mesh>
          </geometry>
          <material>
            <script>
              <name>Gazebo/Red</name>
              <uri>file://media/materials/scripts/gazebo.material</uri>
            </script>
          </material>
        </visual>
        <visual name='crane_x7_gripper_base_link_fixed_joint_lump__camera_base_visual_1'>
          <pose>0 0.0445 0.021525 1.57079 -1.57079 3.14159</pose>
          <geometry>
            <box>
              <size>0.02505 0.09 0.025</size>
            </box>
          </geometry>
        </visual>
        <sensor name='camera1' type='depth'>
          <update_rate>30</update_rate>
          <camera name='depth_camera'>
            <horizontal_fov>1.21126</horizontal_fov>
            <image>
              <width>640</width>
              <height>480</height>
              <format>B8G8R8</format>
            </image>
            <clip>
              <near>0.02</near>
              <far>300</far>
            </clip>
          </camera>
          <plugin name='camera_plugin' filename='libgazebo_ros_openni_kinect.so'>
            <baseline>0.2</baseline>
            <alwaysOn>1</alwaysOn>
            <updateRate>0.0</updateRate>
            <cameraName>camera</cameraName>
            <imageTopicName>fake_cam_color/image_raw</imageTopicName>
            <depthImageTopicName>depth/image_raw</depthImageTopicName>
            <pointCloudTopicName>depth/color/points</pointCloudTopicName>
            <frameName>camera_depth_optical_frame</frameName>
            <pointCloudCutoff>0.105</pointCloudCutoff>
            <pointCloudCutoffMax>10.0</pointCloudCutoffMax>
            <cameraInfoTopicName>fake_cam_color/camera_info</cameraInfoTopicName>
            <depthImageCameraInfoTopicName>depth/camera_info</depthImageCameraInfoTopicName>
            <hackBaseline>0.07</hackBaseline>
            <distortionK1>0.0</distortionK1>
            <distortionK2>0.0</distortionK2>
            <distortionK3>0.0</distortionK3>
            <distortionT1>0.0</distortionT1>
            <distortionT2>0.0</distortionT2>
            <robotNamespace>/</robotNamespace>
          </plugin>
          <pose>0.0175 0.0445 0.02985 3.14159 -1.57079 1.57079</pose>
        </sensor>
        <sensor name='camera2' type='depth'>
          <update_rate>30</update_rate>
          <camera name='color_camera'>
            <horizontal_fov>1.21126</horizontal_fov>
            <image>
              <width>640</width>
              <height>480</height>
              <format>B8G8R8</format>
            </image>
            <clip>
              <near>0.02</near>
              <far>300</far>
            </clip>
          </camera>
          <plugin name='camera_plugin' filename='libgazebo_ros_openni_kinect.so'>
            <baseline>0.2</baseline>
            <alwaysOn>1</alwaysOn>
            <updateRate>0.0</updateRate>
            <cameraName>camera</cameraName>
            <imageTopicName>color/image_raw</imageTopicName>
            <depthImageTopicName>aligned_depth_to_color/image_raw</depthImageTopicName>
            <cameraInfoTopicName>color/camera_info</cameraInfoTopicName>
            <depthImageCameraInfoTopicName>aligned_depth_to_color/camera_info</depthImageCameraInfoTopicName>
            <hackBaseline>0.07</hackBaseline>
            <distortionK1>0.0</distortionK1>
            <distortionK2>0.0</distortionK2>
            <distortionK3>0.0</distortionK3>
            <distortionT1>0.0</distortionT1>
            <distortionT2>0.0</distortionT2>
            <robotNamespace>/</robotNamespace>
          </plugin>
          <pose>0.0325 0.0445 0.02985 3.14159 -1.57079 1.57079</pose>
        </sensor>
        <self_collide>0</self_collide>
        <enable_wind>0</enable_wind>
        <kinematic>0</kinematic>
      </link>
      <joint name='crane_x7_gripper_finger_a_joint' type='revolute'>
        <pose relative_to='crane_x7_gripper_base_link'>-0.012 0 0.024 0 -0 0</pose>
        <parent>crane_x7_gripper_base_link</parent>
        <child>crane_x7_gripper_finger_a_link</child>
        <axis>
          <xyz>0 -1 0</xyz>
          <limit>
            <lower>0.0046</lower>
            <upper>1.62601</upper>
            <effort>4</effort>
            <velocity>4.81711</velocity>
          </limit>
          <dynamics>
            <damping>1e-06</damping>
            <friction>0.8</friction>
            <spring_reference>0</spring_reference>
            <spring_stiffness>0</spring_stiffness>
          </dynamics>
        </axis>
      </joint>
      <link name='crane_x7_gripper_finger_a_link'>
        <pose relative_to='crane_x7_gripper_finger_a_joint'>0 0 0 0 -0 0</pose>
        <inertial>
          <pose>-0.00265 0.00354 0.0269 1.57079 -0 0</pose>
          <mass>0.0158</mass>
          <inertia>
            <ixx>1.01e-05</ixx>
            <ixy>-1.97e-07</ixy>
            <ixz>-9.89e-08</ixz>
            <iyy>4.95e-06</iyy>
            <iyz>5.37e-07</iyz>
            <izz>6.24e-06</izz>
          </inertia>
        </inertial>
        <collision name='crane_x7_gripper_finger_a_link_collision'>
          <pose>0 0 0 1.57079 -0 0</pose>
          <geometry>
            <mesh>
              <scale>1 1 1</scale>
              <uri>/home/shiokaze/catkin_ws/src/crane_x7_description/meshes/collision/wide_two_finger_gripper_finger_a.stl</uri>
            </mesh>
          </geometry>
          <surface>
            <contact>
              <ode/>
            </contact>
            <friction>
              <ode>
                <mu>0.8</mu>
                <mu2>0.8</mu2>
              </ode>
              <torsional>
                <ode/>
              </torsional>
            </friction>
            <bounce/>
          </surface>
          <max_contacts>10</max_contacts>
        </collision>
        <visual name='crane_x7_gripper_finger_a_link_visual'>
          <pose>0 0 0 1.57079 -0 0</pose>
          <geometry>
            <mesh>
              <scale>1 1 1</scale>
              <uri>/home/shiokaze/catkin_ws/src/crane_x7_description/meshes/visual/wide_two_finger_gripper_finger_a.stl</uri>
            </mesh>
          </geometry>
          <material>
            <script>
              <name>Gazebo/Red</name>
              <uri>file://media/materials/scripts/gazebo.material</uri>
            </script>
          </material>
        </visual>
        <self_collide>0</self_collide>
        <enable_wind>0</enable_wind>
        <kinematic>0</kinematic>
      </link>
      <joint name='crane_x7_gripper_finger_b_joint' type='revolute'>
        <pose relative_to='crane_x7_gripper_base_link'>0.012 0 0.024 0 -0 0</pose>
        <parent>crane_x7_gripper_base_link</parent>
        <child>crane_x7_gripper_finger_b_link</child>
        <axis>
          <xyz>0 1 0</xyz>
          <limit>
            <lower>0.0046</lower>
            <upper>1.62601</upper>
            <effort>4</effort>
            <velocity>4.81711</velocity>
          </limit>
          <dynamics>
            <damping>1e-06</damping>
            <friction>0.8</friction>
            <spring_reference>0</spring_reference>
            <spring_stiffness>0</spring_stiffness>
          </dynamics>
        </axis>
      </joint>
      <link name='crane_x7_gripper_finger_b_link'>
        <pose relative_to='crane_x7_gripper_finger_b_joint'>0 0 0 0 -0 0</pose>
        <inertial>
          <pose>0.00301 0.00285 0.0309 1.57079 -0 0</pose>
          <mass>0.0139</mass>
          <inertia>
            <ixx>7.48e-06</ixx>
            <ixy>3.61e-07</ixy>
            <ixz>6.34e-08</ixz>
            <iyy>4.09e-06</iyy>
            <iyz>2.28e-07</iyz>
            <izz>4.37e-06</izz>
          </inertia>
        </inertial>
        <collision name='crane_x7_gripper_finger_b_link_collision'>
          <pose>0 0 0 1.57079 -0 0</pose>
          <geometry>
            <mesh>
              <scale>1 1 1</scale>
              <uri>/home/shiokaze/catkin_ws/src/crane_x7_description/meshes/collision/wide_two_finger_gripper_finger_b.stl</uri>
            </mesh>
          </geometry>
          <surface>
            <contact>
              <ode/>
            </contact>
            <friction>
              <ode>
                <mu>0.8</mu>
                <mu2>0.8</mu2>
              </ode>
              <torsional>
                <ode/>
              </torsional>
            </friction>
            <bounce/>
          </surface>
          <max_contacts>10</max_contacts>
        </collision>
        <visual name='crane_x7_gripper_finger_b_link_visual'>
          <pose>0 0 0 1.57079 -0 0</pose>
          <geometry>
            <mesh>
              <scale>1 1 1</scale>
              <uri>/home/shiokaze/catkin_ws/src/crane_x7_description/meshes/visual/wide_two_finger_gripper_finger_b.stl</uri>
            </mesh>
          </geometry>
          <material>
            <script>
              <name>Gazebo/Red</name>
              <uri>file://media/materials/scripts/gazebo.material</uri>
            </script>
          </material>
        </visual>
        <self_collide>0</self_collide>
        <enable_wind>0</enable_wind>
        <kinematic>0</kinematic>
      </link>
      <plugin name='gazebo_ros_control' filename='libgazebo_ros_control.so'>
        <robotNamespace>/crane_x7</robotNamespace>
        <robotSimType>gazebo_ros_control/DefaultRobotHWSim</robotSimType>
        <legacyModeNS>0</legacyModeNS>
      </plugin>
      <static>0</static>
      <plugin name='crane_x7_gripper_mimic_joint' filename='libroboticsgroup_upatras_gazebo_mimic_joint_plugin.so'>
        <joint>crane_x7_gripper_finger_a_joint</joint>
        <mimicJoint>crane_x7_gripper_finger_b_joint</mimicJoint>
        <multiplier>1</multiplier>
        <robotNamespace>/</robotNamespace>
      </plugin>
      <pose>0 0 1.02 0 -0 0</pose>
    </model>
    <model name='fork'>
      <link name='link_0'>
        <inertial>
          <mass>0.046813</mass>
          <inertia>
            <ixx>1.251e-05</ixx>
            <ixy>0</ixy>
            <ixz>1.626e-05</ixz>
            <iyy>0.00015998</iyy>
            <iyz>0</iyz>
            <izz>0.00015083</izz>
          </inertia>
          <pose>0.07 0 0 0 -0 0</pose>
        </inertial>
        <pose>0 0 0.0325 0 -0 0</pose>
        <gravity>1</gravity>
        <self_collide>0</self_collide>
        <kinematic>0</kinematic>
        <enable_wind>0</enable_wind>
        <visual name='visual'>
          <pose>0 0 0 0 -0 0</pose>
          <geometry>
            <mesh>
              <uri>/home/shiokaze/catkin_ws/src/my_stan/models/meshes/fork.stl</uri>
              <scale>1 1 1</scale>
            </mesh>
          </geometry>
          <material>
            <lighting>1</lighting>
            <script>
              <uri>file://media/materials/scripts/gazebo.material</uri>
              <name>Gazebo/Grey</name>
            </script>
            <shader type='pixel'>
              <normal_map>__default__</normal_map>
            </shader>
            <ambient>0.3 0.3 0.3 1</ambient>
            <diffuse>0.7 0.7 0.7 1</diffuse>
            <specular>0.01 0.01 0.01 1</specular>
            <emissive>0 0 0 1</emissive>
          </material>
          <transparency>0</transparency>
          <cast_shadows>1</cast_shadows>
        </visual>
        <collision name='collision'>
          <laser_retro>0</laser_retro>
          <max_contacts>10</max_contacts>
          <pose>0 0 0 0 -0 0</pose>
          <geometry>
            <mesh>
              <uri>/home/shiokaze/catkin_ws/src/my_stan/models/meshes/fork.stl</uri>
              <scale>1 1 1</scale>
            </mesh>
          </geometry>
          <surface>
            <friction>
              <ode>
                <mu>1</mu>
                <mu2>1</mu2>
                <fdir1>0 0 0</fdir1>
                <slip1>0</slip1>
                <slip2>0</slip2>
              </ode>
              <torsional>
                <coefficient>1</coefficient>
                <patch_radius>0</patch_radius>
                <surface_radius>0</surface_radius>
                <use_patch_radius>1</use_patch_radius>
                <ode>
                  <slip>0</slip>
                </ode>
              </torsional>
            </friction>
            <bounce>
              <restitution_coefficient>0</restitution_coefficient>
              <threshold>1e+06</threshold>
            </bounce>
            <contact>
              <collide_without_contact>0</collide_without_contact>
              <collide_without_contact_bitmask>1</collide_without_contact_bitmask>
              <collide_bitmask>1</collide_bitmask>
              <ode>
                <soft_cfm>0</soft_cfm>
                <soft_erp>0.2</soft_erp>
                <kp>1e+13</kp>
                <kd>1</kd>
                <max_vel>0.01</max_vel>
                <min_depth>0</min_depth>
              </ode>
              <bullet>
                <split_impulse>1</split_impulse>
                <split_impulse_penetration_threshold>-0.01</split_impulse_penetration_threshold>
                <soft_cfm>0</soft_cfm>
                <soft_erp>0.2</soft_erp>
                <kp>1e+13</kp>
                <kd>1</kd>
              </bullet>
            </contact>
          </surface>
        </collision>
      </link>
      <static>0</static>
      <allow_auto_disable>1</allow_auto_disable>
      <pose>0.034901 0.634593 0 0 -0 0</pose>
    </model>
    <state world_name='CRANE-X7 with Table'>
      <sim_time>738 216000000</sim_time>
      <real_time>480 73271392</real_time>
      <wall_time>1668502109 397111648</wall_time>
      <iterations>299952</iterations>
      <model name='crane_x7'>
        <pose>0 0 1.02 1e-05 -1e-06 0</pose>
        <scale>1 1 1</scale>
        <link name='base_link'>
          <pose>0 0 1.02 1e-05 -1e-06 0</pose>
          <velocity>-0 -0 -1e-06 -3.1e-05 -2.3e-05 1e-06</velocity>
          <acceleration>0.002123 -3.9e-05 0.000292 0.004011 0.134941 6e-06</acceleration>
          <wrench>0.000824 -1.5e-05 0.000113 0 -0 0</wrench>
        </link>
        <link name='crane_x7_gripper_base_link'>
          <pose>-0.001209 6.9e-05 1.64399 -0.000289 -0.003016 -0.00757</pose>
          <velocity>-0.000106 7e-06 3.4e-05 -4.2e-05 -0.001425 0.00265</velocity>
          <acceleration>0.012359 0.000951 0.020636 -0.682174 -1.3178 -2.84473</acceleration>
          <wrench>0.008911 0.000686 0.014878 0 -0 0</wrench>
        </link>
        <link name='crane_x7_gripper_finger_a_link'>
          <pose>-0.01328 0.000168 1.66796 -0.00029 -0.007616 -0.007568</pose>
          <velocity>-0.000151 -2.2e-05 1.6e-05 -4.5e-05 -0.001414 0.002664</velocity>
          <acceleration>-0.0708 -0.012031 -0.018841 -0.178979 -1.42002 0.892656</acceleration>
          <wrench>-0.001119 -0.00019 -0.000298 0 -0 0</wrench>
        </link>
        <link name='crane_x7_gripper_finger_b_link'>
          <pose>0.010719 -1.4e-05 1.66803 -0.000289 0.001584 -0.007571</pose>
          <velocity>-0.000156 4.1e-05 5.5e-05 -4e-05 -0.001413 0.002654</velocity>
          <acceleration>-0.082966 -0.006785 0.044502 -0.567018 0.392537 -1.61897</acceleration>
          <wrench>-0.001153 -9.4e-05 0.000619 0 -0 0</wrench>
        </link>
        <link name='crane_x7_lower_arm_fixed_part_link'>
          <pose>-0.000914 3.5e-05 1.375 -0.000114 -0.000954 -0.001191</pose>
          <velocity>-5.7e-05 -1.5e-05 1.1e-05 1.4e-05 0.00016 0.000467</velocity>
          <acceleration>-0.049571 0.005314 0.000472 -1.29417 0.242115 -0.113809</acceleration>
          <wrench>-0.011005 0.00118 0.000105 0 -0 0</wrench>
        </link>
        <link name='crane_x7_lower_arm_revolute_part_link'>
          <pose>-0.001029 5.2e-05 1.49599 -0.000121 -0.000951 -0.004248</pose>
          <velocity>-8.5e-05 -1.1e-05 1.5e-05 -3.2e-05 -2.4e-05 0.001584</velocity>
          <acceleration>-0.02017 0.000944 -0.00272 1.15322 0.144613 -0.920258</acceleration>
          <wrench>-0.004175 0.000195 -0.000563 0 -0 0</wrench>
        </link>
        <link name='crane_x7_shoulder_revolute_part_link'>
          <pose>0 3e-06 1.061 -5e-06 3e-06 -0.003553</pose>
          <velocity>9e-06 -7e-06 1e-06 3.7e-05 2e-06 0.000404</velocity>
          <acceleration>-0.052412 0.00107 2.4e-05 0.086682 -0.095294 -0.223737</acceleration>
          <wrench>-0.01326 0.000271 6e-06 0 -0 0</wrench>
        </link>
        <link name='crane_x7_upper_arm_fixed_part_link'>
          <pose>0 7e-06 1.125 -4.5e-05 -0.003657 -0.003552</pose>
          <velocity>3e-06 -1e-05 3e-06 7.4e-05 7.9e-05 0.000393</velocity>
          <acceleration>-0.070684 0.001688 -0.000788 2.18159 -0.303331 -0.279907</acceleration>
          <wrench>-0.009613 0.00023 -0.000107 0 -0 0</wrench>
        </link>
        <link name='crane_x7_upper_arm_revolute_part_link'>
          <pose>-0.000237 1.1e-05 1.19 -0.000115 -0.003659 -0.001189</pose>
          <velocity>1.2e-05 -1.8e-05 1.2e-05 1.5e-05 -0.000201 0.000469</velocity>
          <acceleration>-0.088119 0.006502 -0.001596 2.05196 0.169147 0.000648</acceleration>
          <wrench>-0.028286 0.002087 -0.000512 0 -0 0</wrench>
        </link>
        <link name='crane_x7_wrist_link'>
          <pose>-0.001152 6.7e-05 1.62499 -8.7e-05 -0.002993 -0.004249</pose>
          <velocity>-9.2e-05 -1e-06 2.9e-05 -0.000129 -0.000201 0.001597</velocity>
          <acceleration>0.033439 -0.003998 0.012349 1.49192 -0.519718 1.15675</acceleration>
          <wrench>0.004681 -0.00056 0.001729 0 -0 0</wrench>
        </link>
      </model>
      <model name='face'>
        <pose>-0.5 0 1.2 0 -0 0</pose>
        <scale>1 1 1</scale>
        <link name='link_0'>
          <pose>-0.5 0 1.2 0 -0 0</pose>
          <velocity>0 0 0 0 -0 0</velocity>
          <acceleration>0 0 0 0 -0 0</acceleration>
          <wrench>0 0 0 0 -0 0</wrench>
        </link>
      </model>
      <model name='fork'>
        <pose>0.399969 -7.3e-05 1.015 3e-06 1.2e-05 0.001</pose>
        <scale>1 1 1</scale>
        <link name='link_0'>
          <pose>0.39997 -7.3e-05 1.0475 3e-06 1.2e-05 0.001</pose>
          <velocity>0 0 0 0 -0 0</velocity>
          <acceleration>0 0 -9.8 -2e-06 1e-06 -3.8e-05</acceleration>
          <wrench>0 0 -0.458767 0 -0 0</wrench>
        </link>
      </model>
      <model name='ground_plane'>
        <pose>0 0 0 0 -0 0</pose>
        <scale>1 1 1</scale>
        <link name='ground_plane::link'>
          <pose>0 0 0 0 -0 0</pose>
          <velocity>0 0 0 0 -0 0</velocity>
          <acceleration>0 0 0 0 -0 0</acceleration>
          <wrench>0 0 0 0 -0 0</wrench>
        </link>
      </model>
      <model name='table'>
        <pose>0.29 0 0 0 -0 1.5708</pose>
        <scale>1 1 1</scale>
        <link name='table::link'>
          <pose>0.29 0 0 0 -0 1.5708</pose>
          <velocity>0 0 0 0 -0 0</velocity>
          <acceleration>0 0 0 0 -0 0</acceleration>
          <wrench>0 0 0 0 -0 0</wrench>
        </link>
      </model>
      <light name='sun'>
        <pose>0 0 10 0 -0 0</pose>
      </light>
    </state>
    <gui fullscreen='0'>
      <camera name='user_camera'>
        <pose>3.51263 -2.60876 2.6976 -0 0.353117 2.50195</pose>
        <view_controller>orbit</view_controller>
        <projection_type>perspective</projection_type>
      </camera>
    </gui>
    <model name='face'>
      <link name='link_0'>
        <inertial>
          <mass>1</mass>
          <inertia>
            <ixx>0.166667</ixx>
            <ixy>0</ixy>
            <ixz>0</ixz>
            <iyy>0.166667</iyy>
            <iyz>0</iyz>
            <izz>0.166667</izz>
          </inertia>
          <pose>0 0 0 0 -0 0</pose>
        </inertial>
        <pose>0 0 0 0 -0 0</pose>
        <gravity>1</gravity>
        <self_collide>0</self_collide>
        <kinematic>0</kinematic>
        <enable_wind>0</enable_wind>
        <visual name='visual'>
          <pose>0 0 0 0 -0 0</pose>
          <geometry>
            <mesh>
              <uri>/home/shiokaze/catkin_ws/src/my_stan/models/meshes/face.stl</uri>
              <scale>1 1 1</scale>
            </mesh>
          </geometry>
          <material>
            <lighting>1</lighting>
            <script>
              <uri>file://media/materials/scripts/gazebo.material</uri>
              <name>Gazebo/Grey</name>
            </script>
            <shader type='pixel'>
              <normal_map>__default__</normal_map>
            </shader>
            <ambient>0.3 0.3 0.3 1</ambient>
            <diffuse>0.7 0.7 0.7 1</diffuse>
            <specular>0.01 0.01 0.01 1</specular>
            <emissive>0 0 0 1</emissive>
          </material>
          <transparency>0</transparency>
          <cast_shadows>1</cast_shadows>
        </visual>
        <collision name='collision'>
          <laser_retro>0</laser_retro>
          <max_contacts>10</max_contacts>
          <pose>0 0 0 0 -0 0</pose>
          <geometry>
            <mesh>
              <uri>/home/shiokaze/catkin_ws/src/my_stan/models/meshes/face.stl</uri>
              <scale>1 1 1</scale>
            </mesh>
          </geometry>
          <surface>
            <friction>
              <ode>
                <mu>1</mu>
                <mu2>1</mu2>
                <fdir1>0 0 0</fdir1>
                <slip1>0</slip1>
                <slip2>0</slip2>
              </ode>
              <torsional>
                <coefficient>1</coefficient>
                <patch_radius>0</patch_radius>
                <surface_radius>0</surface_radius>
                <use_patch_radius>1</use_patch_radius>
                <ode>
                  <slip>0</slip>
                </ode>
              </torsional>
            </friction>
            <bounce>
              <restitution_coefficient>0</restitution_coefficient>
              <threshold>1e+06</threshold>
            </bounce>
            <contact>
              <collide_without_contact>0</collide_without_contact>
              <collide_without_contact_bitmask>1</collide_without_contact_bitmask>
              <collide_bitmask>1</collide_bitmask>
              <ode>
                <soft_cfm>0</soft_cfm>
                <soft_erp>0.2</soft_erp>
                <kp>1e+13</kp>
                <kd>1</kd>
                <max_vel>0.01</max_vel>
                <min_depth>0</min_depth>
              </ode>
              <bullet>
                <split_impulse>1</split_impulse>
                <split_impulse_penetration_threshold>-0.01</split_impulse_penetration_threshold>
                <soft_cfm>0</soft_cfm>
                <soft_erp>0.2</soft_erp>
                <kp>1e+13</kp>
                <kd>1</kd>
              </bullet>
            </contact>
          </surface>
        </collision>
      </link>
      <static>1</static>
      <allow_auto_disable>1</allow_auto_disable>
      <pose>0 0 0 0 -0 0</pose>
    </model>
  </world>
</sdf>
